Workbook

Sheet Legend
A1: Bảng so sánh thí nghiệm — Lab Day 1
A2: Lưu file này thành experiments.xlsx. Mỗi lần chạy là một dòng ở sheet Experiments (số dòng tuỳ bạn, có sẵn 60 dòng). Sheet Seeds và Summary tự tổng hợp.
A4: Quy ước màu
B5: Ô vàng: bạn điền (cấu hình và kết quả đo).
A6: abc | B6: Chữ xanh dương: giá trị đã điền sẵn cho dòng baseline; bạn có thể sửa.
B7: Ô xám: công thức tự tính. Không sửa.
A9: Cách dùng
A10: 1. Sheet Experiments: dòng đầu là baseline mẫu. Điền lr và kết quả; thêm dòng cho mỗi thí nghiệm khác.
A11: 2. Mỗi dòng phải có ảnh riêng figures/<exp_id>.png. Điền tên file vào cột figure_file.
A12: 3. Sheet Seeds: nhập exp_id của các lần chạy baseline với seed khác nhau (đã gợi ý base-s1..3). Sheet tự tính trung bình, σ và 2σ.
A13: 4. Cột beyond_noise cho biết chênh lệch val_macro_f1 so với baseline có vượt 2σ không. Chỉ 'Có' mới là bằng chứng.
A14: 5. Sheet Summary: số dòng theo nhóm và số chủ đề (trong 7) đã được thử.
A16: Từ điển cột (sheet Experiments)
A17: Cột | B17: Ý nghĩa | C17: Cách điền
A18: exp_id | B18: Mã thí nghiệm, duy nhất; trùng tên file ảnh | C18: Tự đặt, ví dụ base-s1, opt-adam-lr1e-3, drop-0.3.
A19: group | B19: Nhóm: baseline | loss | optimizer | hparam | dropout | clipping | amp | init | final | other | C19: Chọn từ danh sách.
A20: description | B20: Bạn đổi gì so với baseline | C20: Một câu.
A21: loss | B21: Hàm mất mát: CE | MSE | C21: Chọn từ danh sách.
A22: optimizer | B22: SGD | SGD+momentum | Adam | AdamW | C22: Chọn từ danh sách.
A23: lr | B23: Tốc độ học η | C23: Ghi số, ví dụ 0.05 hoặc 1e-3.
A24: weight_decay | B24: Hệ số suy giảm trọng số λ | C24: 0 nếu không dùng.
A25: batch | B25: Kích thước lô | C25: Số nguyên.
A26: epochs | B26: Số epoch | C26: Khuyến nghị 20 cho mọi thí nghiệm.
A27: hidden | B27: Các lớp ẩn, ví dụ 256-128 | C27: Chuỗi nối bằng dấu gạch.
A28: dropout | B28: Xác suất tắt nơ-ron q | C28: 0 nếu không dùng.
... A33: step0_loss | B33: Loss trên val ở bước 0 (trước cập nhật đầu tiên) | C33: Kỳ vọng ≈ ln 7 = 1.946 nếu khởi tạo hợp lý.
A34: best_val_loss | B34: Val loss thấp nhất qua các epoch
A35: best_epoch | B35: Epoch đạt best_val_loss | C35: Đếm từ 1.
A36: final_train_loss | B36: Train loss ở epoch cuối (đo ở chế độ eval)
A37: final_val_loss | B37: Val loss ở epoch cuối
A38: val_acc | B38: Val accuracy ở best_epoch | C38: Phân số 0–1, ví dụ 0.8123.
A39: val_macro_f1 | B39: Val macro-F1 ở best_epoch | C39: Phân số 0–1.
A40: time_per_epoch_s | B40: Thời gian trung bình mỗi epoch (giây) | C40: Có torch.cuda.synchronize().
A41: peak_mem_MB | B41: Bộ nhớ GPU cực đại (MB) | C41: torch.cuda.max_memory_allocated()/2**20.
A42: diverged | B42: Loss thành NaN/inf? Y | N | C42: Chọn từ danh sách.
A43: eval_acc | B43: Accuracy trên tập eval | C43: CHỈ điền cho baseline và cấu hình cuối cùng, lấy từ eval_result.json.
A44: eval_macro_f1 | B44: macro-F1 trên tập eval | C44: CHỈ điền cho baseline và cấu hình cuối cùng, lấy từ eval_result.json.
A45: figure_file | B45: Tên file ảnh | C45: figures/<exp_id>.png
A46: notes | B46: Ghi chú | C46: Dự đoán trước, quan sát, lý do thiếu số liệu, lỗi gặp phải...
A47: step0_gap_vs_lnC | B47: step0_loss − ln 7 | C47: Tự tính. Gần 0 là tốt.
...

Sheet Experiments
A1: exp_id | B1: group | C1: description | D1: loss | E1: optimizer | F1: lr | G1: weight_decay | H1: batch | I1: epochs | J1: hidden | K1: dropout | L1: clip_norm | M1: precision | N1: init | O1: seed | P1: step0_loss | Q1: best_val_loss | R1: best_epoch | S1: final_train_loss | T1: final_val_loss | U1: val_acc | V1: val_macro_f1 | W1: time_per_epoch_s | X1: peak_mem_MB | Y1: diverged | Z1: eval_acc | AA1: eval_macro_f1 | AB1: figure_file | AC1: notes | AD1: step0_gap_vs_lnC | AE1: gap_val_minus_train | AF1: delta_val_f1_vs_base | AG1: beyond_noise
A2: base-s1 | B2: baseline | C2: SGD+momentum .05 phải vượt mốc đa số; seed thay đổi thứ tự lô nên điểm có nhiễu. | D2: ce | E2: sgd_momentum | F2: 0.05 | G2: 0 | H2: 512 | I2: 20 | J2: 256-128 | K2: 0 | L2: none | M2: fp32 | N2: he | O2: 1 | P2: 2.2690618 | Q2: 0.25151398 | R2: 20 | S2: 0.22773813 | T2: 0.25151398 | U2: 0.89779695 | V2: 0.83678109 | W2: 1.4388417 | Y2: FALSE | Z2: 0.89736926 | AA2: 0.83985809 | AB2: figures/base-s1.png | AC2: Seed tác động khởi tạo và thứ tự lô. σ từ ba lần chỉ là ước lượng thô.; CPU: CUDA peak memory unavailable; train loss on fixed 50,000 samples | AD2: =IF(P2="","",P2-LN(7)) -> 0.32315168 | AE2: =IF(OR(T2="",S2=""),"",T2-S2) -> 0.02377585 | AF2: =IF(OR(V2="",Seeds!$C$8=""),"",V2-Seeds!$C$8) -> 0.0018243293 | AG2: =IF(OR(AF2="",Seeds!$C$10=""),"",IF(ABS(AF2)>Seeds!$C$10,"Có","Không")) -> Không
A3: base-s2 | B3: baseline | C3: SGD+momentum .05 phải vượt mốc đa số; seed thay đổi thứ tự lô nên điểm có nhiễu. | D3: ce | E3: sgd_momentum | F3: 0.05 | G3: 0 | H3: 512 | I3: 20 | J3: 256-128 | K3: 0 | L3: none | M3: fp32 | N3: he | O3: 2 | P3: 1.9781567 | Q3: 0.25419174 | R3: 17 | S3: 0.23647227 | T3: 0.25803163 | U3: 0.89716228 | V3: 0.82734625 | W3: 1.3363791 | Y3: FALSE | AB3: figures/base-s2.png | AC3: Seed tác động khởi tạo và thứ tự lô. σ từ ba lần chỉ là ước lượng thô.; CPU: CUDA peak memory unavailable; train loss on fixed 50,000 samples | AD3: =IF(P3="","",P3-LN(7)) -> 0.032246528 | AE3: =IF(OR(T3="",S3=""),"",T3-S3) -> 0.021559364 | AF3: =IF(OR(V3="",Seeds!$C$8=""),"",V3-Seeds!$C$8) -> -0.007610506 | AG3: =IF(OR(AF3="",Seeds!$C$10=""),"",IF(ABS(AF3)>Seeds!$C$10,"Có","Không")) -> Không
A4: base-s3 | B4: baseline | C4: SGD+momentum .05 phải vượt mốc đa số; seed thay đổi thứ tự lô nên điểm có nhiễu. | D4: ce | E4: sgd_momentum | F4: 0.05 | G4: 0 | H4: 512 | I4: 20 | J4: 256-128 | K4: 0 | L4: none | M4: fp32 | N4: he | O4: 3 | P4: 1.90054 | Q4: 0.24774569 | R4: 19 | S4: 0.25004749 | T4: 0.26812717 | U4: 0.90036789 | V4: 0.84074293 | W4: 1.4006396 | Y4: FALSE | AB4: figures/base-s3.png | AC4: Seed tác động khởi tạo và thứ tự lô. σ từ ba lần chỉ là ước lượng thô.; CPU: CUDA peak memory unavailable; train loss on fixed 50,000 samples | AD4: =IF(P4="","",P4-LN(7)) -> -0.045370144 | AE4: =IF(OR(T4="",S4=""),"",T4-S4) -> 0.018079676 | AF4: =IF(OR(V4="",Seeds!$C$8=""),"",V4-Seeds!$C$8) -> 0.0057861767 | AG4: =IF(OR(AF4="",Seeds!$C$10=""),"",IF(ABS(AF4)>Seeds!$C$10,"Có","Không")) -> Không
A5: opt-adam-lr001 | B5: optimizer | C5: Adam cập nhật thích nghi có thể hội tụ nhanh hơn; mỗi optimizer cần thử nhiều lr. | D5: ce | E5: adam | F5: 0.001 | G5: 0 | H5: 512 | I5: 20 | J5: 256-128 | K5: 0 | L5: none | M5: fp32 | N5: he | O5: 1 | P5: 2.2690618 | Q5: 0.24227806 | R5: 18 | S5: 0.2303282 | T5: 0.25048269 | U5: 0.90320776 | V5: 0.84598497 | W5: 1.9263086 | Y5: FALSE | AB5: figures/opt-adam-lr001.png | AC5: Momentum tích luỹ hướng gradient; Adam chia bước theo moment bậc hai. So lr tốt nhất trong phạm vi đã thử, không khẳng định tối ưu toàn cục.; CPU: CUDA peak memory unavailable; train loss on fixed 50,000 samples | AD5: =IF(P5="","",P5-LN(7)) -> 0.32315168 | AE5: =IF(OR(T5="",S5=""),"",T5-S5) -> 0.020154496 | AF5: =IF(OR(V5="",Seeds!$C$8=""),"",V5-Seeds!$C$8) -> 0.011028217 | AG5: =IF(OR(AF5="",Seeds!$C$10=""),"",IF(ABS(AF5)>Seeds!$C$10,"Có","Không")) -> Không
A6: opt-adam-lr003 | B6: optimizer | C6: Adam cập nhật thích nghi có thể hội tụ nhanh hơn; mỗi optimizer cần thử nhiều lr. | D6: ce | E6: adam | F6: 0.003 | G6: 0 | H6: 512 | I6: 20 | J6: 256-128 | K6: 0 | L6: none | M6: fp32 | N6: he | O6: 1 | P6: 2.2690618 | Q6: 0.20946919 | R6: 20 | S6: 0.18028654 | T6: 0.20946919 | U6: 0.91800951 | V6: 0.87791714 | W6: 1.7069166 | Y6: FALSE | Z6: 0.91590579 | AA6: 0.87766004 | AB6: figures/opt-adam-lr003.png | AC6: Momentum tích luỹ hướng gradient; Adam chia bước theo moment bậc hai. So lr tốt nhất trong phạm vi đã thử, không khẳng định tối ưu toàn cục.; CPU: CUDA peak memory unavailable; train loss on fixed 50,000 samples | AD6: =IF(P6="","",P6-LN(7)) -> 0.32315168 | AE6: =IF(OR(T6="",S6=""),"",T6-S6) -> 0.029182648 | AF6: =IF(OR(V6="",Seeds!$C$8=""),"",V6-Seeds!$C$8) -> 0.042960388 | AG6: =IF(OR(AF6="",Seeds!$C$10=""),"",IF(ABS(AF6)>Seeds!$C$10,"Có","Không")) -> Có
A7: opt-sgdm-lr01 | B7: optimizer | C7: Adam cập nhật thích nghi có thể hội tụ nhanh hơn; mỗi optimizer cần thử nhiều lr. | D7: ce | E7: sgd_momentum | F7: 0.01 | G7: 0 | H7: 512 | I7: 20 | J7: 256-128 | K7: 0 | L7: none | M7: fp32 | N7: he | O7: 1 | P7: 2.2690618 | Q7: 0.31723543 | R7: 19 | S7: 0.31916477 | T7: 0.32973352 | U7: 0.87166799 | V7: 0.76490071 | W7: 1.5621033 | Y7: FALSE | AB7: figures/opt-sgdm-lr01.png | AC7: Momentum tích luỹ hướng gradient; Adam chia bước theo moment bậc hai. So lr tốt nhất trong phạm vi đã thử, không khẳng định tối ưu toàn cục.; CPU: CUDA peak memory unavailable; train loss on fixed 50,000 samples | AD7: =IF(P7="","",P7-LN(7)) -> 0.32315168 | AE7: =IF(OR(T7="",S7=""),"",T7-S7) -> 0.010568746 | AF7: =IF(OR(V7="",Seeds!$C$8=""),"",V7-Seeds!$C$8) -> -0.070056049 | AG7: =IF(OR(AF7="",Seeds!$C$10=""),"",IF(ABS(AF7)>Seeds!$C$10,"Có","Không")) -> Có
A8: opt-sgdm-lr10 | B8: optimizer | C8: Adam cập nhật thích nghi có thể hội tụ nhanh hơn; mỗi optimizer cần thử nhiều lr. | D8: ce | E8: sgd_momentum | F8: 0.1 | G8: 0 | H8: 512 | I8: 20 | J8: 256-128 | K8: 0 | L8: none | M8: fp32 | N8: he | O8: 1 | P8: 2.2690618 | Q8: 0.23205981 | R8: 20 | S8: 0.20749785 | T8: 0.23205981 | U8: 0.90685441 | V8: 0.8546047 | W8: 1.5601077 | Y8: FALSE | AB8: figures/opt-sgdm-lr10.png | AC8: Momentum tích luỹ hướng gradient; Adam chia bước theo moment bậc hai. So lr tốt nhất trong phạm vi đã thử, không khẳng định tối ưu toàn cục.; CPU: CUDA peak memory unavailable; train loss on fixed 50,000 samples | AD8: =IF(P8="","",P8-LN(7)) -> 0.32315168 | AE8: =IF(OR(T8="",S8=""),"",T8-S8) -> 0.024561965 | AF8: =IF(OR(V8="",Seeds!$C$8=""),"",V8-Seeds!$C$8) -> 0.019647945 | AG8: =IF(OR(AF8="",Seeds!$C$10=""),"",IF(ABS(AF8)>Seeds!$C$10,"Có","Không")) -> Có
A9: loss-mse | B9: loss | C9: MSE logit/one-hot dự kiến học chậm hơn CE vì không trực tiếp tối ưu log-likelihood. | D9: mse | E9: sgd_momentum | F9: 0.05 | G9: 0 | H9: 512 | I9: 20 | J9: 256-128 | K9: 0 | L9: none | M9: fp32 | N9: he | O9: 1 | P9: 0.63585032 | Q9: 0.032426376 | R9: 20 | S9: 0.031746036 | T9: 0.032426376 | U9: 0.85541404 | V9: 0.683903 | W9: 1.4517766 | Y9: FALSE | AB9: figures/loss-mse.png | AC9: CE có gradient logit p-y. MSE ở đây dùng logit thô, mean trên 7 tọa độ: gradient 2(z-onehot)/7; không so trị số loss giữa CE và MSE.; CPU: CUDA peak memory unavailable; train loss on fixed 50,000 samples | AD9: =IF(P9="","",P9-LN(7)) -> -1.3100598 | AE9: =IF(OR(T9="",S9=""),"",T9-S9) -> 0.00068033956 | AF9: =IF(OR(V9="",Seeds!$C$8=""),"",V9-Seeds!$C$8) -> -0.15105376 | AG9: =IF(OR(AF9="",Seeds!$C$10=""),"",IF(ABS(AF9)>Seeds!$C$10,"Có","Không")) -> Có
A10: lr-high | B10: hparam | C10: lr cao .5 có thể làm loss/gradient dao động hơn .05; chưa chắc phân kỳ. | D10: ce | E10: sgd_momentum | F10: 0.5 | G10: 0 | H10: 512 | I10: 20 | J10: 256-128 | K10: 0 | L10: none | M10: fp32 | N10: he | O10: 1 | P10: 2.2690618 | Q10: 0.26027616 | R10: 20 | S10: 0.23145006 | T10: 0.26027616 | U10: 0.89944278 | V10: 0.82992051 | W10: 1.5548645 | Y10: FALSE | AB10: figures/lr-high.png | AC10: Tăng lr làm bước cập nhật lớn hơn; cùng 20 epoch và batch 512 giữ số bước như nhau.; CPU: CUDA peak memory unavailable; train loss on fixed 50,000 samples | AD10: =IF(P10="","",P10-LN(7)) -> 0.32315168 | AE10: =IF(OR(T10="",S10=""),"",T10-S10) -> 0.028826105 | AF10: =IF(OR(V10="",Seeds!$C$8=""),"",V10-Seeds!$C$8) -> -0.0050362508 | AG10: =IF(OR(AF10="",Seeds!$C$10=""),"",IF(ABS(AF10)>Seeds!$C$10,"Có","Không")) -> Không
A11: dropout-q02 | B11: dropout | C11: q=.2 có thể giảm gap train–val nhưng làm chậm học nếu baseline chưa quá khớp. | D11: ce | E11: sgd_momentum | F11: 0.05 | G11: 0 | H11: 512 | I11: 20 | J11: 256-128 | K11: 0.2 | L11: none | M11: fp32 | N11: he | O11: 1 | P11: 2.2690618 | Q11: 0.30800286 | R11: 19 | S11: 0.30153725 | T11: 0.30946699 | U11: 0.87602461 | V11: 0.79495488 | W11: 3.237279 | Y11: FALSE | AB11: figures/dropout-q02.png | AC11: Dropout tăng nhiễu lúc train; cả train loss và val loss đều đo eval mode. Gap cuối dương là dấu hiệu cần xét, không đủ để kết luận mọi regularization có lợi.; CPU: CUDA peak memory unavailable; train loss on fixed 50,000 samples | AD11: =IF(P11="","",P11-LN(7)) -> 0.32315168 | AE11: =IF(OR(T11="",S11=""),"",T11-S11) -> 0.007929738 | AF11: =IF(OR(V11="",Seeds!$C$8=""),"",V11-Seeds!$C$8) -> -0.040001874 | AG11: =IF(OR(AF11="",Seeds!$C$10=""),"",IF(ABS(AF11)>Seeds!$C$10,"Có","Không")) -> Có
A12: clip-high | B12: clipping | C12: Cắt ở phân vị 90% gradient baseline; có thể giảm gai ở lr cao, không chắc tăng F1. | D12: ce | E12: sgd_momentum | F12: 0.5 | G12: 0 | H12: 512 | I12: 20 | J12: 256-128 | K12: 0 | L12: 1.0470242 | M12: fp32 | N12: he | O12: 1 | P12: 2.2690618 | Q12: 0.23647674 | R12: 19 | S12: 0.21025886 | T12: 0.23828383 | U12: 0.90625202 | V12: 0.84801752 | W12: 1.5202138 | Y12: FALSE | AB12: figures/clip-high.png | AC12: Global L2 clipping nhân gradient với min(1,c/||g||); giữ hướng nhưng giảm bước. Nó không sửa được nhãn sai hoặc lr quá nhỏ.; CPU: CUDA peak memory unavailable; train loss on fixed 50,000 samples | AD12: =IF(P12="","",P12-LN(7)) -> 0.32315168 | AE12: =IF(OR(T12="",S12=""),"",T12-S12) -> 0.02802497 | AF12: =IF(OR(V12="",Seeds!$C$8=""),"",V12-Seeds!$C$8) -> 0.013060762 | AG12: =IF(OR(AF12="",Seeds!$C$10=""),"",IF(ABS(AF12)>Seeds!$C$10,"Có","Không")) -> Không
A13: clip-normal | B13: clipping | C13: Cắt ở phân vị 90% gradient baseline; có thể giảm gai ở lr cao, không chắc tăng F1. | D13: ce | E13: sgd_momentum | F13: 0.05 | G13: 0 | H13: 512 | I13: 20 | J13: 256-128 | K13: 0 | L13: 1.0470242 | M13: fp32 | N13: he | O13: 1 | P13: 2.2690618 | Q13: 0.25004924 | R13: 19 | S13: 0.24300361 | T13: 0.26604658 | U13: 0.90017426 | V13: 0.84251446 | W13: 1.4739163 | Y13: FALSE | AB13: figures/clip-normal.png | AC13: Global L2 clipping nhân gradient với min(1,c/||g||); giữ hướng nhưng giảm bước. Nó không sửa được nhãn sai hoặc lr quá nhỏ.; CPU: CUDA peak memory unavailable; train loss on fixed 50,000 samples | AD13: =IF(P13="","",P13-LN(7)) -> 0.32315168 | AE13: =IF(OR(T13="",S13=""),"",T13-S13) -> 0.023042961 | AF13: =IF(OR(V13="",Seeds!$C$8=""),"",V13-Seeds!$C$8) -> 0.0075577005 | AG13: =IF(OR(AF13="",Seeds!$C$10=""),"",IF(ABS(AF13)>Seeds!$C$10,"Có","Không")) -> Không
A14: amp-bf16 | B14: amp | C14: BF16 CPU có thể nhanh hơn nếu CPU hỗ trợ; F1 có thể lệch do làm tròn. | D14: ce | E14: sgd_momentum | F14: 0.05 | G14: 0 | H14: 512 | I14: 20 | J14: 256-128 | K14: 0 | L14: none | M14: bf16 | N14: he | O14: 1 | P14: 2.2690618 | Q14: 0.25251262 | R14: 19 | S14: 0.244125 | T14: 0.26600034 | U14: 0.89754954 | V14: 0.84016213 | W14: 3.3085305 | Y14: FALSE | AB14: figures/amp-bf16.png | AC14: Autocast BF16 chỉ bọc forward/loss, tham số và optimizer vẫn FP32. CPU không có CUDA nên không đo FP16 hay CUDA peak memory; thời gian phụ thuộc phần cứng.; CPU: CUDA peak memory unavailable; train loss on fixed 50,000 samples | AD14: =IF(P14="","",P14-LN(7)) -> 0.32315168 | AE14: =IF(OR(T14="",S14=""),"",T14-S14) -> 0.02187534 | AF14: =IF(OR(V14="",Seeds!$C$8=""),"",V14-Seeds!$C$8) -> 0.0052053688 | AG14: =IF(OR(AF14="",Seeds!$C$10=""),"",IF(ABS(AF14)>Seeds!$C$10,"Có","Không")) -> Không
A15: init-xavier | B15: init | C15: Xavier có phương sai nhỏ hơn He; zeros giữ đối xứng và chỉ học bias đầu ra. | D15: ce | E15: sgd_momentum | F15: 0.05 | G15: 0 | H15: 512 | I15: 20 | J15: 256-128 | K15: 0 | L15: none | M15: fp32 | N15: xavier | O15: 1 | P15: 2.0221762 | Q15: 0.25794562 | R15: 17 | S15: 0.24204827 | T15: 0.26319928 | U15: 0.89584992 | V15: 0.82923708 | W15: 1.4349164 | Y15: FALSE | AB15: figures/init-xavier.png | AC15: ReLU cần phá đối xứng: zeros làm gradient các lớp ẩn bằng 0. He dùng Var=2/fan_in; Xavier dùng 2/(fan_in+fan_out). Stats đo sau từng Linear.; CPU: CUDA peak memory unavailable; train loss on fixed 50,000 samples | AD15: =IF(P15="","",P15-LN(7)) -> 0.07626608 | AE15: =IF(OR(T15="",S15=""),"",T15-S15) -> 0.021151006 | AF15: =IF(OR(V15="",Seeds!$C$8=""),"",V15-Seeds!$C$8) -> -0.0057196753 | AG15: =IF(OR(AF15="",Seeds!$C$10=""),"",IF(ABS(AF15)>Seeds!$C$10,"Có","Không")) -> Không
A16: init-zeros | B16: init | C16: Xavier có phương sai nhỏ hơn He; zeros giữ đối xứng và chỉ học bias đầu ra. | D16: ce | E16: sgd_momentum | F16: 0.05 | G16: 0 | H16: 512 | I16: 20 | J16: 256-128 | K16: 0 | L16: none | M16: fp32 | N16: zeros | O16: 1 | P16: 1.9459096 | Q16: 1.2051804 | R16: 16 | S16: 1.2020197 | T16: 1.2054051 | U16: 0.48759708 | V16: 0.09364999 | W16: 1.4280344 | Y16: FALSE | AB16: figures/init-zeros.png | AC16: ReLU cần phá đối xứng: zeros làm gradient các lớp ẩn bằng 0. He dùng Var=2/fan_in; Xavier dùng 2/(fan_in+fan_out). Stats đo sau từng Linear.; CPU: CUDA peak memory unavailable; train loss on fixed 50,000 samples | AD16: =IF(P16="","",P16-LN(7)) -> -5.2972395e-07 | AE16: =IF(OR(T16="",S16=""),"",T16-S16) -> 0.0033853506 | AF16: =IF(OR(V16="",Seeds!$C$8=""),"",V16-Seeds!$C$8) -> -0.74130677 | AG16: =IF(OR(AF16="",Seeds!$C$10=""),"",IF(ABS(AF16)>Seeds!$C$10,"Có","Không")) -> Có
AD17: =IF(P17="","",P17-LN(7)) | AE17: =IF(OR(T17="",S17=""),"",T17-S17) | AF17: =IF(OR(V17="",Seeds!$C$8=""),"",V17-Seeds!$C$8) | AG17: =IF(OR(AF17="",Seeds!$C$10=""),"",IF(ABS(AF17)>Seeds!$C$10,"Có","Không"))
AD18: =IF(P18="","",P18-LN(7)) | AE18: =IF(OR(T18="",S18=""),"",T18-S18) | AF18: =IF(OR(V18="",Seeds!$C$8=""),"",V18-Seeds!$C$8) | AG18: =IF(OR(AF18="",Seeds!$C$10=""),"",IF(ABS(AF18)>Seeds!$C$10,"Có","Không"))
AD19: =IF(P19="","",P19-LN(7)) | AE19: =IF(OR(T19="",S19=""),"",T19-S19) | AF19: =IF(OR(V19="",Seeds!$C$8=""),"",V19-Seeds!$C$8) | AG19: =IF(OR(AF19="",Seeds!$C$10=""),"",IF(ABS(AF19)>Seeds!$C$10,"Có","Không"))
AD20: =IF(P20="","",P20-LN(7)) | AE20: =IF(OR(T20="",S20=""),"",T20-S20) | AF20: =IF(OR(V20="",Seeds!$C$8=""),"",V20-Seeds!$C$8) | AG20: =IF(OR(AF20="",Seeds!$C$10=""),"",IF(ABS(AF20)>Seeds!$C$10,"Có","Không"))
AD21: =IF(P21="","",P21-LN(7)) | AE21: =IF(OR(T21="",S21=""),"",T21-S21) | AF21: =IF(OR(V21="",Seeds!$C$8=""),"",V21-Seeds!$C$8) | AG21: =IF(OR(AF21="",Seeds!$C$10=""),"",IF(ABS(AF21)>Seeds!$C$10,"Có","Không"))
AD22: =IF(P22="","",P22-LN(7)) | AE22: =IF(OR(T22="",S22=""),"",T22-S22) | AF22: =IF(OR(V22="",Seeds!$C$8=""),"",V22-Seeds!$C$8) | AG22: =IF(OR(AF22="",Seeds!$C$10=""),"",IF(ABS(AF22)>Seeds!$C$10,"Có","Không"))
AD23: =IF(P23="","",P23-LN(7)) | AE23: =IF(OR(T23="",S23=""),"",T23-S23) | AF23: =IF(OR(V23="",Seeds!$C$8=""),"",V23-Seeds!$C$8) | AG23: =IF(OR(AF23="",Seeds!$C$10=""),"",IF(ABS(AF23)>Seeds!$C$10,"Có","Không"))
AD24: =IF(P24="","",P24-LN(7)) | AE24: =IF(OR(T24="",S24=""),"",T24-S24) | AF24: =IF(OR(V24="",Seeds!$C$8=""),"",V24-Seeds!$C$8) | AG24: =IF(OR(AF24="",Seeds!$C$10=""),"",IF(ABS(AF24)>Seeds!$C$10,"Có","Không"))
AD25: =IF(P25="","",P25-LN(7)) | AE25: =IF(OR(T25="",S25=""),"",T25-S25) | AF25: =IF(OR(V25="",Seeds!$C$8=""),"",V25-Seeds!$C$8) | AG25: =IF(OR(AF25="",Seeds!$C$10=""),"",IF(ABS(AF25)>Seeds!$C$10,"Có","Không"))
AD26: =IF(P26="","",P26-LN(7)) | AE26: =IF(OR(T26="",S26=""),"",T26-S26) | AF26: =IF(OR(V26="",Seeds!$C$8=""),"",V26-Seeds!$C$8) | AG26: =IF(OR(AF26="",Seeds!$C$10=""),"",IF(ABS(AF26)>Seeds!$C$10,"Có","Không"))
AD27: =IF(P27="","",P27-LN(7)) | AE27: =IF(OR(T27="",S27=""),"",T27-S27) | AF27: =IF(OR(V27="",Seeds!$C$8=""),"",V27-Seeds!$C$8) | AG27: =IF(OR(AF27="",Seeds!$C$10=""),"",IF(ABS(AF27)>Seeds!$C$10,"Có","Không"))
AD28: =IF(P28="","",P28-LN(7)) | AE28: =IF(OR(T28="",S28=""),"",T28-S28) | AF28: =IF(OR(V28="",Seeds!$C$8=""),"",V28-Seeds!$C$8) | AG28: =IF(OR(AF28="",Seeds!$C$10=""),"",IF(ABS(AF28)>Seeds!$C$10,"Có","Không"))
... AD61: =IF(P61="","",P61-LN(7)) | AE61: =IF(OR(T61="",S61=""),"",T61-S61) | AF61: =IF(OR(V61="",Seeds!$C$8=""),"",V61-Seeds!$C$8) | AG61: =IF(OR(AF61="",Seeds!$C$10=""),"",IF(ABS(AF61)>Seeds!$C$10,"Có","Không"))

Sheet Seeds
A1: exp_id baseline (nhập) | B1: val_acc | C1: val_macro_f1 | D1: best_val_loss
A2: base-s1 | B2: 0.89779695 | C2: 0.83678109 | D2: 0.25151398
A3: base-s2 | B3: 0.89716228 | C3: 0.82734625 | D3: 0.25419174
A4: base-s3 | B4: 0.90036789 | C4: 0.84074293 | D4: 0.24774569
B5: =IF($A5="","",IFERROR(IF(INDEX(Experiments!$U$2:$U$61,MATCH($A5,Experiments!$A$2:$A$61,0))="","",INDEX(Experiments!$U$2:$U$61,MATCH($A5,Experiments!$A$2:$A$61,0))),"")) | C5: =IF($A5="","",IFERROR(IF(INDEX(Experiments!$V$2:$V$61,MATCH($A5,Experiments!$A$2:$A$61,0))="","",INDEX(Experiments!$V$2:$V$61,MATCH($A5,Experiments!$A$2:$A$61,0))),"")) | D5: =IF($A5="","",IFERROR(IF(INDEX(Experiments!$Q$2:$Q$61,MATCH($A5,Experiments!$A$2:$A$61,0))="","",INDEX(Experiments!$Q$2:$Q$61,MATCH($A5,Experiments!$A$2:$A$61,0))),""))
B6: =IF($A6="","",IFERROR(IF(INDEX(Experiments!$U$2:$U$61,MATCH($A6,Experiments!$A$2:$A$61,0))="","",INDEX(Experiments!$U$2:$U$61,MATCH($A6,Experiments!$A$2:$A$61,0))),"")) | C6: =IF($A6="","",IFERROR(IF(INDEX(Experiments!$V$2:$V$61,MATCH($A6,Experiments!$A$2:$A$61,0))="","",INDEX(Experiments!$V$2:$V$61,MATCH($A6,Experiments!$A$2:$A$61,0))),"")) | D6: =IF($A6="","",IFERROR(IF(INDEX(Experiments!$Q$2:$Q$61,MATCH($A6,Experiments!$A$2:$A$61,0))="","",INDEX(Experiments!$Q$2:$Q$61,MATCH($A6,Experiments!$A$2:$A$61,0))),""))
A8: mean | B8: 0.89844237 | C8: 0.83495676 | D8: 0.25115047
A9: std (mẫu) | B9: 0.0016974732 | C9: 0.0068821443 | D9: 0.0032383602
A10: 2σ (ngưỡng nhiễu) | B10: 0.0033949465 | C10: 0.013764289 | D10: 0.0064767204
A12: Nhập exp_id của các lần chạy baseline (khác seed) ở cột A. Cần ≥ 2 seed để có σ.
A13: Mọi chênh lệch nhỏ hơn 2σ không được coi là bằng chứng. Với ít seed, σ chỉ là ước lượng thô; nêu rõ trong báo cáo.

Sheet Summary
A1: group | B1: số dòng | C1: đã điền val_macro_f1 | D1: val_macro_f1 cao nhất | E1: val_macro_f1 thấp nhất | F1: val_acc cao nhất | G1: đã thử chủ đề này? | H1: nhận xét ngắn (bạn viết)
A2: baseline | B2: 3 | C2: 3 | D2: 0.84074293 | E2: 0.82734625 | F2: 0.90036789 | G2: — | H2: base-s1; base-s2; base-s3
A3: loss | B3: 1 | C3: 1 | D3: 0.683903 | E3: 0.683903 | F3: 0.85541404 | G3: Có | H3: loss-mse
A4: optimizer | B4: 4 | C4: 4 | D4: 0.87791714 | E4: 0.76490071 | F4: 0.91800951 | G4: Có | H4: opt-adam-lr001; opt-adam-lr003; opt-sgdm-lr01; opt-sgdm-lr10
A5: hparam | B5: 1 | C5: 1 | D5: 0.82992051 | E5: 0.82992051 | F5: 0.89944278 | G5: Có | H5: lr-high
A6: dropout | B6: 1 | C6: 1 | D6: 0.79495488 | E6: 0.79495488 | F6: 0.87602461 | G6: Có | H6: dropout-q02
A7: clipping | B7: 2 | C7: 2 | D7: 0.84801752 | E7: 0.84251446 | F7: 0.90625202 | G7: Có | H7: clip-high; clip-normal
A8: amp | B8: 1 | C8: 1 | D8: 0.84016213 | E8: 0.84016213 | F8: 0.89754954 | G8: Có | H8: amp-bf16
A9: init | B9: 2 | C9: 2 | D9: 0.82923708 | E9: 0.09364999 | F9: 0.89584992 | G9: Có | H9: init-xavier; init-zeros
A10: final | B10: 0 | C10: 0 | D10: =IF(C10=0,"",_xlfn.MAXIFS(Experiments!$V$2:$V$61,Experiments!$B$2:$B$61,A10)) | E10: =IF(C10=0,"",_xlfn.MINIFS(Experiments!$V$2:$V$61,Experiments!$B$2:$B$61,A10)) | F10: =IF(C10=0,"",_xlfn.MAXIFS(Experiments!$U$2:$U$61,Experiments!$B$2:$B$61,A10)) | G10: — | H10: Không chạy trên phần cứng hiện tại
A11: other | B11: 0 | C11: 0 | D11: =IF(C11=0,"",_xlfn.MAXIFS(Experiments!$V$2:$V$61,Experiments!$B$2:$B$61,A11)) | E11: =IF(C11=0,"",_xlfn.MINIFS(Experiments!$V$2:$V$61,Experiments!$B$2:$B$61,A11)) | F11: =IF(C11=0,"",_xlfn.MAXIFS(Experiments!$U$2:$U$61,Experiments!$B$2:$B$61,A11)) | G11: — | H11: Không chạy trên phần cứng hiện tại
A13: Số chủ đề (trong 7) đã thử: | D13: =COUNTIF(G2:G11,"Có") -> 7
A14: 7 chủ đề: loss, optimizer, hparam, dropout, clipping, amp, init. Một chủ đề 'đã thử' khi có ≥ 1 dòng có val_macro_f1.
A17: Diagnostics / supplementary measurements | B17: Value | C17: Source
A18: params | B18: 47879 | C18: health_checks.json
A19: shape logits | B19: [8, 7] | C19: health_checks.json
A20: ln7 | B20: 1.9459101 | C20: reference
A21: overfit20_final_loss | B21: 5.3167023e-06 | C21: health_checks.json
A22: majority_val_acc | B22: 0.48759708 | C22: health_checks.json
A23: total_epoch_time_s | B23: 526.81657 | C23: all histories
A24: gradient net.0.weight | B24: 0.50705498 | C24: health_checks.json
A25: gradient net.0.bias | B25: 0.34224012 | C25: health_checks.json
A26: gradient net.2.weight | B26: 2.0212278 | C26: health_checks.json
A27: gradient net.2.bias | B27: 0.44387364 | C27: health_checks.json
A28: gradient net.4.weight | B28: 1.9604558 | C28: health_checks.json
A29: gradient net.4.bias | B29: 0.57245553 | C29: health_checks.json
A30: base-s1 grad_norm_p90 | B30: 1.0470242 | C30: base-s1
A31: base-s1 max_grad_norm | B31: 2.8710766 | C31: base-s1
... A119: init-zeros activation_std_linear3 | B119: 0 | C119: init-zeros
A121: baseline eval class | B121: support | C121: precision | D121: recall | E121: F1
A122: 0 | B122: 42368 | C122: 0.93900494 | D122: 0.84771526 | E122: 0.89102795
A123: 1 | B123: 56661 | C123: 0.8822203 | D123: 0.95287764 | E123: 0.9161887
A124: 2 | B124: 7151 | C124: 0.89507865 | D124: 0.86729129 | E124: 0.88096591
A125: 3 | B125: 549 | C125: 0.79291045 | D125: 0.77413479 | E125: 0.78341014
A126: 4 | B126: 1899 | C126: 0.84961885 | D126: 0.64560295 | E126: 0.7336924
A127: 5 | B127: 3473 | C127: 0.78107218 | D127: 0.75093579 | E127: 0.76570757
A128: 6 | B128: 4102 | C128: 0.86712511 | D128: 0.95294978 | E128: 0.90801394
A129: baseline confusion matrix (true rows / predicted columns)
A130: 35916 | B130: 5862 | C130: 4 | D130: 0 | E130: 40 | F130: 12 | G130: 534
A131: 2162 | B131: 53991 | C131: 104 | D131: 2 | E131: 161 | F131: 176 | G131: 65
...
